try {
  console.log('Inicio');
  let suma = 15 + 15;
  console.log(`El resultado es ${suma}`);
} catch (error) {
  console.log('Se ignora cath porque no hay errores');
}

/* **************************************************************** */

try {
  console.log('Inicio');
  let suma = 15 + 30;
  console.log(`El resultado es ${resultado}`);
} catch (error) {
  console.log(`Hay un error! ${error}`);
}

//console.log(`El resultado es ${resultado}`)